2025-10-15 10:51:10,778 INFO    MainThread:12927 [wandb_init.py:setup_run_log_directory():705] Logging user logs to /home/patryk/Desktop/AiR_ISS/sem2/DSN/lab3/wandb/run-20251015_105110-vxqfbrid/logs/debug.log
2025-10-15 10:51:10,778 INFO    MainThread:12927 [wandb_init.py:setup_run_log_directory():706] Logging internal logs to /home/patryk/Desktop/AiR_ISS/sem2/DSN/lab3/wandb/run-20251015_105110-vxqfbrid/logs/debug-internal.log
2025-10-15 10:51:10,778 INFO    MainThread:12927 [wandb_init.py:monkeypatch_ipython():624] configuring jupyter hooks <wandb.sdk.wandb_init._WandbInit object at 0x763a4232c7f0>
2025-10-15 10:51:10,778 INFO    MainThread:12927 [wandb_init.py:init():832] calling init triggers
2025-10-15 10:51:10,778 INFO    MainThread:12927 [wandb_init.py:init():837] wandb.init called with sweep_config: {}
config: {'_wandb': {}}
2025-10-15 10:51:11,719 INFO    MainThread:12927 [wandb_init.py:init():880] starting backend
2025-10-15 10:51:11,719 INFO    MainThread:12927 [wandb_init.py:init():883] sending inform_init request
2025-10-15 10:51:11,722 INFO    MainThread:12927 [wandb_init.py:init():891] backend started and connected
2025-10-15 10:51:11,725 INFO    MainThread:12927 [wandb_run.py:_label_probe_notebook():1330] probe notebook
2025-10-15 10:51:11,725 INFO    MainThread:12927 [wandb_run.py:_label_probe_notebook():1340] Unable to probe notebook: 'NoneType' object has no attribute 'get'
2025-10-15 10:51:11,725 INFO    MainThread:12927 [wandb_init.py:init():961] updated telemetry
2025-10-15 10:51:11,733 INFO    MainThread:12927 [wandb_init.py:init():985] communicating run to backend with 90.0 second timeout
2025-10-15 10:51:12,454 INFO    MainThread:12927 [wandb_init.py:init():1036] starting run threads in backend
2025-10-15 10:51:12,632 INFO    MainThread:12927 [wandb_run.py:_console_start():2506] atexit reg
2025-10-15 10:51:12,633 INFO    MainThread:12927 [wandb_run.py:_redirect():2354] redirect: wrap_raw
2025-10-15 10:51:12,633 INFO    MainThread:12927 [wandb_run.py:_redirect():2423] Wrapping output streams.
2025-10-15 10:51:12,633 INFO    MainThread:12927 [wandb_run.py:_redirect():2446] Redirects installed.
2025-10-15 10:51:12,634 INFO    MainThread:12927 [wandb_init.py:init():1076] run started, returning control to user process
2025-10-15 10:51:12,634 INFO    MainThread:12927 [wandb_watch.py:_watch():68] Watching
2025-10-15 10:52:41,387 INFO    MainThread:12927 [wandb_init.py:_post_run_cell_hook():594] [no run ID] resuming backend
2025-10-15 10:52:42,354 ERROR   Thread-2 (_watch_pipe_fd):12927 [redirect.py:_on_write():664] [all runs] error in stdout callback
Traceback (most recent call last):
  File "/home/patryk/Desktop/venv/ML_venv/lib/python3.10/site-packages/wandb/sdk/lib/redirect.py", line 662, in _on_write
    cb(written_data)
  File "/home/patryk/Desktop/venv/ML_venv/lib/python3.10/site-packages/wandb/sdk/wandb_run.py", line 2427, in <lambda>
    lambda data: self._console_raw_callback("stdout", data),
  File "/home/patryk/Desktop/venv/ML_venv/lib/python3.10/site-packages/wandb/sdk/wandb_run.py", line 399, in wrapper
    return func(self, *args, **kwargs)
  File "/home/patryk/Desktop/venv/ML_venv/lib/python3.10/site-packages/wandb/sdk/wandb_run.py", line 457, in wrapper_fn
    return func(self, *args, **kwargs)
  File "/home/patryk/Desktop/venv/ML_venv/lib/python3.10/site-packages/wandb/sdk/wandb_run.py", line 1595, in _console_raw_callback
    self._backend.interface.publish_output_raw(name, data)
  File "/home/patryk/Desktop/venv/ML_venv/lib/python3.10/site-packages/wandb/sdk/interface/interface.py", line 802, in publish_output_raw
    self._publish_output_raw(o)
  File "/home/patryk/Desktop/venv/ML_venv/lib/python3.10/site-packages/wandb/sdk/interface/interface_shared.py", line 37, in _publish_output_raw
    self._publish(rec)
  File "/home/patryk/Desktop/venv/ML_venv/lib/python3.10/site-packages/wandb/sdk/interface/interface_sock.py", line 43, in _publish
    self._asyncer.run(lambda: self._client.publish(request))
  File "/home/patryk/Desktop/venv/ML_venv/lib/python3.10/site-packages/wandb/sdk/lib/asyncio_manager.py", line 136, in run
    return future.result()
  File "/usr/lib/python3.10/concurrent/futures/_base.py", line 458, in result
    return self.__get_result()
  File "/usr/lib/python3.10/concurrent/futures/_base.py", line 403, in __get_result
    raise self._exception
  File "/home/patryk/Desktop/venv/ML_venv/lib/python3.10/site-packages/wandb/sdk/lib/asyncio_manager.py", line 219, in _wrap
    return await fn()
  File "/home/patryk/Desktop/venv/ML_venv/lib/python3.10/site-packages/wandb/sdk/lib/service/service_client.py", line 38, in publish
    await self._send_server_request(request)
  File "/home/patryk/Desktop/venv/ML_venv/lib/python3.10/site-packages/wandb/sdk/lib/service/service_client.py", line 64, in _send_server_request
    await self._writer.drain()
  File "/usr/lib/python3.10/asyncio/streams.py", line 371, in drain
    await self._protocol._drain_helper()
  File "/usr/lib/python3.10/asyncio/streams.py", line 167, in _drain_helper
    raise ConnectionResetError('Connection lost')
ConnectionResetError: Connection lost
